[2017-01-12 09:45:22,653] {models.py:154} INFO - Filling up the DagBag from /home/ubuntu/airflow/dags/time_splitter.py
[2017-01-12 09:45:23,405] {models.py:154} INFO - Filling up the DagBag from /home/ubuntu/airflow/dags/time_splitter.py
[2017-01-12 09:45:23,442] {models.py:1196} INFO - 
--------------------------------------------------------------------------------
Starting attempt 1 of 2
--------------------------------------------------------------------------------

[2017-01-12 09:45:23,450] {models.py:1219} INFO - Executing <Task(BashOperator): task_2_split_time> on 2017-01-12 08:30:00
[2017-01-12 09:45:23,465] {bash_operator.py:55} INFO - tmp dir root location: 
/tmp
[2017-01-12 09:45:23,466] {bash_operator.py:64} INFO - Temporary script location :/tmp/airflowtmp_5svt74y//tmp/airflowtmp_5svt74y/task_2_split_time4tfaos6s
[2017-01-12 09:45:23,466] {bash_operator.py:65} INFO - Running command: python split_into_time.py
[2017-01-12 09:45:23,468] {bash_operator.py:73} INFO - Output:
[2017-01-12 09:45:23,482] {bash_operator.py:77} INFO - python: can't open file 'split_into_time.py': [Errno 2] No such file or directory
[2017-01-12 09:45:23,483] {bash_operator.py:80} INFO - Command exited with return code 2
[2017-01-12 09:45:23,483] {models.py:1286} ERROR - Bash command failed
Traceback (most recent call last):
  File "/home/ubuntu/venv/lib/python3.5/site-packages/airflow/models.py", line 1245, in run
    result = task_copy.execute(context=context)
  File "/home/ubuntu/venv/lib/python3.5/site-packages/airflow/operators/bash_operator.py", line 83, in execute
    raise AirflowException("Bash command failed")
airflow.exceptions.AirflowException: Bash command failed
[2017-01-12 09:45:23,484] {models.py:1298} INFO - Marking task as UP_FOR_RETRY
[2017-01-12 09:45:23,492] {models.py:1327} ERROR - Bash command failed
[2017-01-12 09:46:34,566] {models.py:154} INFO - Filling up the DagBag from /home/ubuntu/airflow/dags/time_splitter.py
[2017-01-12 09:46:36,226] {models.py:154} INFO - Filling up the DagBag from /home/ubuntu/airflow/dags/time_splitter.py
[2017-01-12 09:46:36,287] {models.py:1196} INFO - 
--------------------------------------------------------------------------------
Starting attempt 2 of 2
--------------------------------------------------------------------------------

[2017-01-12 09:46:36,302] {models.py:1219} INFO - Executing <Task(BashOperator): task_2_split_time> on 2017-01-12 08:30:00
[2017-01-12 09:46:36,334] {bash_operator.py:55} INFO - tmp dir root location: 
/tmp
[2017-01-12 09:46:36,334] {bash_operator.py:64} INFO - Temporary script location :/tmp/airflowtmpsdkbmus5//tmp/airflowtmpsdkbmus5/task_2_split_timeq450463x
[2017-01-12 09:46:36,335] {bash_operator.py:65} INFO - Running command: python split_into_time.py
[2017-01-12 09:46:36,338] {bash_operator.py:73} INFO - Output:
[2017-01-12 09:46:36,388] {bash_operator.py:77} INFO - python: can't open file 'split_into_time.py': [Errno 2] No such file or directory
[2017-01-12 09:46:36,391] {bash_operator.py:80} INFO - Command exited with return code 2
[2017-01-12 09:46:36,392] {models.py:1286} ERROR - Bash command failed
Traceback (most recent call last):
  File "/home/ubuntu/venv/lib/python3.5/site-packages/airflow/models.py", line 1245, in run
    result = task_copy.execute(context=context)
  File "/home/ubuntu/venv/lib/python3.5/site-packages/airflow/operators/bash_operator.py", line 83, in execute
    raise AirflowException("Bash command failed")
airflow.exceptions.AirflowException: Bash command failed
[2017-01-12 09:46:36,393] {models.py:1304} INFO - All retries failed; marking task as FAILED
[2017-01-12 09:46:36,409] {models.py:1327} ERROR - Bash command failed
