[2017-01-12 09:40:46,831] {models.py:154} INFO - Filling up the DagBag from /home/ubuntu/airflow/dags/time_splitter.py
[2017-01-12 09:40:47,710] {models.py:154} INFO - Filling up the DagBag from /home/ubuntu/airflow/dags/time_splitter.py
[2017-01-12 09:40:47,747] {models.py:1196} INFO - 
--------------------------------------------------------------------------------
Starting attempt 1 of 2
--------------------------------------------------------------------------------

[2017-01-12 09:40:47,756] {models.py:1219} INFO - Executing <Task(BashOperator): task_2_split_time> on 2017-01-12 00:00:00
[2017-01-12 09:40:47,776] {bash_operator.py:55} INFO - tmp dir root location: 
/tmp
[2017-01-12 09:40:47,777] {bash_operator.py:64} INFO - Temporary script location :/tmp/airflowtmponcrhh02//tmp/airflowtmponcrhh02/task_2_split_timexrb5jobj
[2017-01-12 09:40:47,777] {bash_operator.py:65} INFO - Running command: python split_into_time.py
[2017-01-12 09:40:47,779] {bash_operator.py:73} INFO - Output:
[2017-01-12 09:40:47,795] {bash_operator.py:77} INFO - python: can't open file 'split_into_time.py': [Errno 2] No such file or directory
[2017-01-12 09:40:47,795] {bash_operator.py:80} INFO - Command exited with return code 2
[2017-01-12 09:40:47,796] {models.py:1286} ERROR - Bash command failed
Traceback (most recent call last):
  File "/home/ubuntu/venv/lib/python3.5/site-packages/airflow/models.py", line 1245, in run
    result = task_copy.execute(context=context)
  File "/home/ubuntu/venv/lib/python3.5/site-packages/airflow/operators/bash_operator.py", line 83, in execute
    raise AirflowException("Bash command failed")
airflow.exceptions.AirflowException: Bash command failed
[2017-01-12 09:40:47,797] {models.py:1298} INFO - Marking task as UP_FOR_RETRY
[2017-01-12 09:40:47,806] {models.py:1327} ERROR - Bash command failed
[2017-01-12 09:42:01,249] {models.py:154} INFO - Filling up the DagBag from /home/ubuntu/airflow/dags/time_splitter.py
[2017-01-12 09:42:02,044] {models.py:154} INFO - Filling up the DagBag from /home/ubuntu/airflow/dags/time_splitter.py
[2017-01-12 09:42:02,082] {models.py:1196} INFO - 
--------------------------------------------------------------------------------
Starting attempt 2 of 2
--------------------------------------------------------------------------------

[2017-01-12 09:42:02,091] {models.py:1219} INFO - Executing <Task(BashOperator): task_2_split_time> on 2017-01-12 00:00:00
[2017-01-12 09:42:02,107] {bash_operator.py:55} INFO - tmp dir root location: 
/tmp
[2017-01-12 09:42:02,107] {bash_operator.py:64} INFO - Temporary script location :/tmp/airflowtmpuenu9mtv//tmp/airflowtmpuenu9mtv/task_2_split_timelsoft2l9
[2017-01-12 09:42:02,108] {bash_operator.py:65} INFO - Running command: python split_into_time.py
[2017-01-12 09:42:02,109] {bash_operator.py:73} INFO - Output:
[2017-01-12 09:42:02,124] {bash_operator.py:77} INFO - python: can't open file 'split_into_time.py': [Errno 2] No such file or directory
[2017-01-12 09:42:02,124] {bash_operator.py:80} INFO - Command exited with return code 2
[2017-01-12 09:42:02,125] {models.py:1286} ERROR - Bash command failed
Traceback (most recent call last):
  File "/home/ubuntu/venv/lib/python3.5/site-packages/airflow/models.py", line 1245, in run
    result = task_copy.execute(context=context)
  File "/home/ubuntu/venv/lib/python3.5/site-packages/airflow/operators/bash_operator.py", line 83, in execute
    raise AirflowException("Bash command failed")
airflow.exceptions.AirflowException: Bash command failed
[2017-01-12 09:42:02,126] {models.py:1304} INFO - All retries failed; marking task as FAILED
[2017-01-12 09:42:02,134] {models.py:1327} ERROR - Bash command failed
