[2017-01-12 09:44:20,791] {models.py:154} INFO - Filling up the DagBag from /home/ubuntu/airflow/dags/time_splitter.py
[2017-01-12 09:44:21,567] {models.py:154} INFO - Filling up the DagBag from /home/ubuntu/airflow/dags/time_splitter.py
[2017-01-12 09:44:21,609] {models.py:1196} INFO - 
--------------------------------------------------------------------------------
Starting attempt 1 of 2
--------------------------------------------------------------------------------

[2017-01-12 09:44:21,622] {models.py:1219} INFO - Executing <Task(BashOperator): task_2_split_time> on 2017-01-12 06:00:00
[2017-01-12 09:44:21,641] {bash_operator.py:55} INFO - tmp dir root location: 
/tmp
[2017-01-12 09:44:21,642] {bash_operator.py:64} INFO - Temporary script location :/tmp/airflowtmp9htv0jfv//tmp/airflowtmp9htv0jfv/task_2_split_timejy4i2995
[2017-01-12 09:44:21,642] {bash_operator.py:65} INFO - Running command: python split_into_time.py
[2017-01-12 09:44:21,644] {bash_operator.py:73} INFO - Output:
[2017-01-12 09:44:21,659] {bash_operator.py:77} INFO - python: can't open file 'split_into_time.py': [Errno 2] No such file or directory
[2017-01-12 09:44:21,660] {bash_operator.py:80} INFO - Command exited with return code 2
[2017-01-12 09:44:21,660] {models.py:1286} ERROR - Bash command failed
Traceback (most recent call last):
  File "/home/ubuntu/venv/lib/python3.5/site-packages/airflow/models.py", line 1245, in run
    result = task_copy.execute(context=context)
  File "/home/ubuntu/venv/lib/python3.5/site-packages/airflow/operators/bash_operator.py", line 83, in execute
    raise AirflowException("Bash command failed")
airflow.exceptions.AirflowException: Bash command failed
[2017-01-12 09:44:21,661] {models.py:1298} INFO - Marking task as UP_FOR_RETRY
[2017-01-12 09:44:21,669] {models.py:1327} ERROR - Bash command failed
[2017-01-12 09:45:28,929] {models.py:154} INFO - Filling up the DagBag from /home/ubuntu/airflow/dags/time_splitter.py
[2017-01-12 09:45:29,747] {models.py:154} INFO - Filling up the DagBag from /home/ubuntu/airflow/dags/time_splitter.py
[2017-01-12 09:45:29,791] {models.py:1196} INFO - 
--------------------------------------------------------------------------------
Starting attempt 2 of 2
--------------------------------------------------------------------------------

[2017-01-12 09:45:29,801] {models.py:1219} INFO - Executing <Task(BashOperator): task_2_split_time> on 2017-01-12 06:00:00
[2017-01-12 09:45:29,817] {bash_operator.py:55} INFO - tmp dir root location: 
/tmp
[2017-01-12 09:45:29,818] {bash_operator.py:64} INFO - Temporary script location :/tmp/airflowtmpn_5at6rl//tmp/airflowtmpn_5at6rl/task_2_split_timeoqjt7_qg
[2017-01-12 09:45:29,818] {bash_operator.py:65} INFO - Running command: python split_into_time.py
[2017-01-12 09:45:29,820] {bash_operator.py:73} INFO - Output:
[2017-01-12 09:45:29,833] {bash_operator.py:77} INFO - python: can't open file 'split_into_time.py': [Errno 2] No such file or directory
[2017-01-12 09:45:29,834] {bash_operator.py:80} INFO - Command exited with return code 2
[2017-01-12 09:45:29,834] {models.py:1286} ERROR - Bash command failed
Traceback (most recent call last):
  File "/home/ubuntu/venv/lib/python3.5/site-packages/airflow/models.py", line 1245, in run
    result = task_copy.execute(context=context)
  File "/home/ubuntu/venv/lib/python3.5/site-packages/airflow/operators/bash_operator.py", line 83, in execute
    raise AirflowException("Bash command failed")
airflow.exceptions.AirflowException: Bash command failed
[2017-01-12 09:45:29,836] {models.py:1304} INFO - All retries failed; marking task as FAILED
[2017-01-12 09:45:29,847] {models.py:1327} ERROR - Bash command failed
