[2017-01-12 09:44:46,939] {models.py:154} INFO - Filling up the DagBag from /home/ubuntu/airflow/dags/time_splitter.py
[2017-01-12 09:44:48,623] {models.py:154} INFO - Filling up the DagBag from /home/ubuntu/airflow/dags/time_splitter.py
[2017-01-12 09:44:48,665] {models.py:1196} INFO - 
--------------------------------------------------------------------------------
Starting attempt 1 of 2
--------------------------------------------------------------------------------

[2017-01-12 09:44:48,675] {models.py:1219} INFO - Executing <Task(BashOperator): task_2_split_time> on 2017-01-12 07:00:00
[2017-01-12 09:44:48,691] {bash_operator.py:55} INFO - tmp dir root location: 
/tmp
[2017-01-12 09:44:48,692] {bash_operator.py:64} INFO - Temporary script location :/tmp/airflowtmpe1slyxap//tmp/airflowtmpe1slyxap/task_2_split_time8_5vqtw2
[2017-01-12 09:44:48,692] {bash_operator.py:65} INFO - Running command: python split_into_time.py
[2017-01-12 09:44:48,694] {bash_operator.py:73} INFO - Output:
[2017-01-12 09:44:48,707] {bash_operator.py:77} INFO - python: can't open file 'split_into_time.py': [Errno 2] No such file or directory
[2017-01-12 09:44:48,708] {bash_operator.py:80} INFO - Command exited with return code 2
[2017-01-12 09:44:48,709] {models.py:1286} ERROR - Bash command failed
Traceback (most recent call last):
  File "/home/ubuntu/venv/lib/python3.5/site-packages/airflow/models.py", line 1245, in run
    result = task_copy.execute(context=context)
  File "/home/ubuntu/venv/lib/python3.5/site-packages/airflow/operators/bash_operator.py", line 83, in execute
    raise AirflowException("Bash command failed")
airflow.exceptions.AirflowException: Bash command failed
[2017-01-12 09:44:48,710] {models.py:1298} INFO - Marking task as UP_FOR_RETRY
[2017-01-12 09:44:48,718] {models.py:1327} ERROR - Bash command failed
[2017-01-12 09:45:51,553] {models.py:154} INFO - Filling up the DagBag from /home/ubuntu/airflow/dags/time_splitter.py
[2017-01-12 09:45:52,403] {models.py:154} INFO - Filling up the DagBag from /home/ubuntu/airflow/dags/time_splitter.py
[2017-01-12 09:45:52,459] {models.py:1196} INFO - 
--------------------------------------------------------------------------------
Starting attempt 2 of 2
--------------------------------------------------------------------------------

[2017-01-12 09:45:52,471] {models.py:1219} INFO - Executing <Task(BashOperator): task_2_split_time> on 2017-01-12 07:00:00
[2017-01-12 09:45:52,488] {bash_operator.py:55} INFO - tmp dir root location: 
/tmp
[2017-01-12 09:45:52,489] {bash_operator.py:64} INFO - Temporary script location :/tmp/airflowtmpx2592sqw//tmp/airflowtmpx2592sqw/task_2_split_timeplw1tb27
[2017-01-12 09:45:52,489] {bash_operator.py:65} INFO - Running command: python split_into_time.py
[2017-01-12 09:45:52,491] {bash_operator.py:73} INFO - Output:
[2017-01-12 09:45:52,506] {bash_operator.py:77} INFO - python: can't open file 'split_into_time.py': [Errno 2] No such file or directory
[2017-01-12 09:45:52,506] {bash_operator.py:80} INFO - Command exited with return code 2
[2017-01-12 09:45:52,507] {models.py:1286} ERROR - Bash command failed
Traceback (most recent call last):
  File "/home/ubuntu/venv/lib/python3.5/site-packages/airflow/models.py", line 1245, in run
    result = task_copy.execute(context=context)
  File "/home/ubuntu/venv/lib/python3.5/site-packages/airflow/operators/bash_operator.py", line 83, in execute
    raise AirflowException("Bash command failed")
airflow.exceptions.AirflowException: Bash command failed
[2017-01-12 09:45:52,508] {models.py:1304} INFO - All retries failed; marking task as FAILED
[2017-01-12 09:45:52,515] {models.py:1327} ERROR - Bash command failed
