[2017-01-12 10:15:33,523] {models.py:154} INFO - Filling up the DagBag from /home/ubuntu/airflow/dags/time_splitter.py
[2017-01-12 10:15:34,938] {models.py:154} INFO - Filling up the DagBag from /home/ubuntu/airflow/dags/time_splitter.py
[2017-01-12 10:15:35,032] {models.py:1196} INFO - 
--------------------------------------------------------------------------------
Starting attempt 1 of 2
--------------------------------------------------------------------------------

[2017-01-12 10:15:35,156] {models.py:1219} INFO - Executing <Task(BashOperator): task_2_split_time> on 2017-01-12 09:30:00
[2017-01-12 10:15:35,179] {bash_operator.py:55} INFO - tmp dir root location: 
/tmp
[2017-01-12 10:15:35,179] {bash_operator.py:64} INFO - Temporary script location :/tmp/airflowtmpr2gt911o//tmp/airflowtmpr2gt911o/task_2_split_timewrsl9y22
[2017-01-12 10:15:35,179] {bash_operator.py:65} INFO - Running command: python split_into_time.py
[2017-01-12 10:15:35,182] {bash_operator.py:73} INFO - Output:
[2017-01-12 10:15:35,200] {bash_operator.py:77} INFO - python: can't open file 'split_into_time.py': [Errno 2] No such file or directory
[2017-01-12 10:15:35,201] {bash_operator.py:80} INFO - Command exited with return code 2
[2017-01-12 10:15:35,201] {models.py:1286} ERROR - Bash command failed
Traceback (most recent call last):
  File "/home/ubuntu/venv/lib/python3.5/site-packages/airflow/models.py", line 1245, in run
    result = task_copy.execute(context=context)
  File "/home/ubuntu/venv/lib/python3.5/site-packages/airflow/operators/bash_operator.py", line 83, in execute
    raise AirflowException("Bash command failed")
airflow.exceptions.AirflowException: Bash command failed
[2017-01-12 10:15:35,203] {models.py:1298} INFO - Marking task as UP_FOR_RETRY
[2017-01-12 10:15:35,211] {models.py:1327} ERROR - Bash command failed
[2017-01-12 10:16:41,064] {models.py:154} INFO - Filling up the DagBag from /home/ubuntu/airflow/dags/time_splitter.py
[2017-01-12 10:16:41,825] {models.py:154} INFO - Filling up the DagBag from /home/ubuntu/airflow/dags/time_splitter.py
[2017-01-12 10:16:41,871] {models.py:1196} INFO - 
--------------------------------------------------------------------------------
Starting attempt 2 of 2
--------------------------------------------------------------------------------

[2017-01-12 10:16:41,883] {models.py:1219} INFO - Executing <Task(BashOperator): task_2_split_time> on 2017-01-12 09:30:00
[2017-01-12 10:16:41,900] {bash_operator.py:55} INFO - tmp dir root location: 
/tmp
[2017-01-12 10:16:41,900] {bash_operator.py:64} INFO - Temporary script location :/tmp/airflowtmpfqyt83km//tmp/airflowtmpfqyt83km/task_2_split_time48g1hlqd
[2017-01-12 10:16:41,900] {bash_operator.py:65} INFO - Running command: python split_into_time.py
[2017-01-12 10:16:41,903] {bash_operator.py:73} INFO - Output:
[2017-01-12 10:16:41,921] {bash_operator.py:77} INFO - python: can't open file 'split_into_time.py': [Errno 2] No such file or directory
[2017-01-12 10:16:41,921] {bash_operator.py:80} INFO - Command exited with return code 2
[2017-01-12 10:16:41,922] {models.py:1286} ERROR - Bash command failed
Traceback (most recent call last):
  File "/home/ubuntu/venv/lib/python3.5/site-packages/airflow/models.py", line 1245, in run
    result = task_copy.execute(context=context)
  File "/home/ubuntu/venv/lib/python3.5/site-packages/airflow/operators/bash_operator.py", line 83, in execute
    raise AirflowException("Bash command failed")
airflow.exceptions.AirflowException: Bash command failed
[2017-01-12 10:16:41,923] {models.py:1304} INFO - All retries failed; marking task as FAILED
[2017-01-12 10:16:41,933] {models.py:1327} ERROR - Bash command failed
