[2017-01-12 09:42:07,163] {models.py:154} INFO - Filling up the DagBag from /home/ubuntu/airflow/dags/time_splitter.py
[2017-01-12 09:42:07,935] {models.py:154} INFO - Filling up the DagBag from /home/ubuntu/airflow/dags/time_splitter.py
[2017-01-12 09:42:07,972] {models.py:1196} INFO - 
--------------------------------------------------------------------------------
Starting attempt 1 of 2
--------------------------------------------------------------------------------

[2017-01-12 09:42:07,981] {models.py:1219} INFO - Executing <Task(BashOperator): task_2_split_time> on 2017-01-12 03:00:00
[2017-01-12 09:42:07,996] {bash_operator.py:55} INFO - tmp dir root location: 
/tmp
[2017-01-12 09:42:07,997] {bash_operator.py:64} INFO - Temporary script location :/tmp/airflowtmpg0q9w1sy//tmp/airflowtmpg0q9w1sy/task_2_split_timeep06ytvp
[2017-01-12 09:42:07,997] {bash_operator.py:65} INFO - Running command: python split_into_time.py
[2017-01-12 09:42:07,999] {bash_operator.py:73} INFO - Output:
[2017-01-12 09:42:08,012] {bash_operator.py:77} INFO - python: can't open file 'split_into_time.py': [Errno 2] No such file or directory
[2017-01-12 09:42:08,013] {bash_operator.py:80} INFO - Command exited with return code 2
[2017-01-12 09:42:08,013] {models.py:1286} ERROR - Bash command failed
Traceback (most recent call last):
  File "/home/ubuntu/venv/lib/python3.5/site-packages/airflow/models.py", line 1245, in run
    result = task_copy.execute(context=context)
  File "/home/ubuntu/venv/lib/python3.5/site-packages/airflow/operators/bash_operator.py", line 83, in execute
    raise AirflowException("Bash command failed")
airflow.exceptions.AirflowException: Bash command failed
[2017-01-12 09:42:08,014] {models.py:1298} INFO - Marking task as UP_FOR_RETRY
[2017-01-12 09:42:08,022] {models.py:1327} ERROR - Bash command failed
[2017-01-12 09:43:42,431] {models.py:154} INFO - Filling up the DagBag from /home/ubuntu/airflow/dags/time_splitter.py
[2017-01-12 09:43:43,412] {models.py:154} INFO - Filling up the DagBag from /home/ubuntu/airflow/dags/time_splitter.py
[2017-01-12 09:43:43,613] {models.py:1196} INFO - 
--------------------------------------------------------------------------------
Starting attempt 2 of 2
--------------------------------------------------------------------------------

[2017-01-12 09:43:43,626] {models.py:1219} INFO - Executing <Task(BashOperator): task_2_split_time> on 2017-01-12 03:00:00
[2017-01-12 09:43:43,645] {bash_operator.py:55} INFO - tmp dir root location: 
/tmp
[2017-01-12 09:43:43,646] {bash_operator.py:64} INFO - Temporary script location :/tmp/airflowtmpzq7to869//tmp/airflowtmpzq7to869/task_2_split_timesv1qyewr
[2017-01-12 09:43:43,646] {bash_operator.py:65} INFO - Running command: python split_into_time.py
[2017-01-12 09:43:43,648] {bash_operator.py:73} INFO - Output:
[2017-01-12 09:43:43,675] {bash_operator.py:77} INFO - python: can't open file 'split_into_time.py': [Errno 2] No such file or directory
[2017-01-12 09:43:43,676] {bash_operator.py:80} INFO - Command exited with return code 2
[2017-01-12 09:43:43,677] {models.py:1286} ERROR - Bash command failed
Traceback (most recent call last):
  File "/home/ubuntu/venv/lib/python3.5/site-packages/airflow/models.py", line 1245, in run
    result = task_copy.execute(context=context)
  File "/home/ubuntu/venv/lib/python3.5/site-packages/airflow/operators/bash_operator.py", line 83, in execute
    raise AirflowException("Bash command failed")
airflow.exceptions.AirflowException: Bash command failed
[2017-01-12 09:43:43,679] {models.py:1304} INFO - All retries failed; marking task as FAILED
[2017-01-12 09:43:43,690] {models.py:1327} ERROR - Bash command failed
