[2017-01-12 09:41:36,112] {models.py:154} INFO - Filling up the DagBag from /home/ubuntu/airflow/dags/time_splitter.py
[2017-01-12 09:41:37,339] {models.py:154} INFO - Filling up the DagBag from /home/ubuntu/airflow/dags/time_splitter.py
[2017-01-12 09:41:37,430] {models.py:1196} INFO - 
--------------------------------------------------------------------------------
Starting attempt 1 of 2
--------------------------------------------------------------------------------

[2017-01-12 09:41:37,443] {models.py:1219} INFO - Executing <Task(BashOperator): task_2_split_time> on 2017-01-12 02:00:00
[2017-01-12 09:41:37,464] {bash_operator.py:55} INFO - tmp dir root location: 
/tmp
[2017-01-12 09:41:37,465] {bash_operator.py:64} INFO - Temporary script location :/tmp/airflowtmpwfn6nqfe//tmp/airflowtmpwfn6nqfe/task_2_split_time5av_ll8w
[2017-01-12 09:41:37,465] {bash_operator.py:65} INFO - Running command: python split_into_time.py
[2017-01-12 09:41:37,467] {bash_operator.py:73} INFO - Output:
[2017-01-12 09:41:37,492] {bash_operator.py:77} INFO - python: can't open file 'split_into_time.py': [Errno 2] No such file or directory
[2017-01-12 09:41:37,494] {bash_operator.py:80} INFO - Command exited with return code 2
[2017-01-12 09:41:37,495] {models.py:1286} ERROR - Bash command failed
Traceback (most recent call last):
  File "/home/ubuntu/venv/lib/python3.5/site-packages/airflow/models.py", line 1245, in run
    result = task_copy.execute(context=context)
  File "/home/ubuntu/venv/lib/python3.5/site-packages/airflow/operators/bash_operator.py", line 83, in execute
    raise AirflowException("Bash command failed")
airflow.exceptions.AirflowException: Bash command failed
[2017-01-12 09:41:37,498] {models.py:1298} INFO - Marking task as UP_FOR_RETRY
[2017-01-12 09:41:37,515] {models.py:1327} ERROR - Bash command failed
[2017-01-12 09:43:10,369] {models.py:154} INFO - Filling up the DagBag from /home/ubuntu/airflow/dags/time_splitter.py
[2017-01-12 09:43:11,676] {models.py:154} INFO - Filling up the DagBag from /home/ubuntu/airflow/dags/time_splitter.py
[2017-01-12 09:43:11,716] {models.py:1196} INFO - 
--------------------------------------------------------------------------------
Starting attempt 2 of 2
--------------------------------------------------------------------------------

[2017-01-12 09:43:11,727] {models.py:1219} INFO - Executing <Task(BashOperator): task_2_split_time> on 2017-01-12 02:00:00
[2017-01-12 09:43:11,743] {bash_operator.py:55} INFO - tmp dir root location: 
/tmp
[2017-01-12 09:43:11,743] {bash_operator.py:64} INFO - Temporary script location :/tmp/airflowtmpl3y3e8xd//tmp/airflowtmpl3y3e8xd/task_2_split_time24csbq5a
[2017-01-12 09:43:11,743] {bash_operator.py:65} INFO - Running command: python split_into_time.py
[2017-01-12 09:43:11,745] {bash_operator.py:73} INFO - Output:
[2017-01-12 09:43:11,767] {bash_operator.py:77} INFO - python: can't open file 'split_into_time.py': [Errno 2] No such file or directory
[2017-01-12 09:43:11,768] {bash_operator.py:80} INFO - Command exited with return code 2
[2017-01-12 09:43:11,768] {models.py:1286} ERROR - Bash command failed
Traceback (most recent call last):
  File "/home/ubuntu/venv/lib/python3.5/site-packages/airflow/models.py", line 1245, in run
    result = task_copy.execute(context=context)
  File "/home/ubuntu/venv/lib/python3.5/site-packages/airflow/operators/bash_operator.py", line 83, in execute
    raise AirflowException("Bash command failed")
airflow.exceptions.AirflowException: Bash command failed
[2017-01-12 09:43:11,770] {models.py:1304} INFO - All retries failed; marking task as FAILED
[2017-01-12 09:43:11,778] {models.py:1327} ERROR - Bash command failed
