[2017-01-12 09:42:44,670] {models.py:154} INFO - Filling up the DagBag from /home/ubuntu/airflow/dags/time_splitter.py
[2017-01-12 09:42:46,334] {models.py:154} INFO - Filling up the DagBag from /home/ubuntu/airflow/dags/time_splitter.py
[2017-01-12 09:42:46,401] {models.py:1196} INFO - 
--------------------------------------------------------------------------------
Starting attempt 1 of 2
--------------------------------------------------------------------------------

[2017-01-12 09:42:46,416] {models.py:1219} INFO - Executing <Task(BashOperator): task_2_split_time> on 2017-01-12 04:00:00
[2017-01-12 09:42:46,439] {bash_operator.py:55} INFO - tmp dir root location: 
/tmp
[2017-01-12 09:42:46,440] {bash_operator.py:64} INFO - Temporary script location :/tmp/airflowtmpt0_p2upr//tmp/airflowtmpt0_p2upr/task_2_split_timevbyz_py4
[2017-01-12 09:42:46,440] {bash_operator.py:65} INFO - Running command: python split_into_time.py
[2017-01-12 09:42:46,442] {bash_operator.py:73} INFO - Output:
[2017-01-12 09:42:46,466] {bash_operator.py:77} INFO - python: can't open file 'split_into_time.py': [Errno 2] No such file or directory
[2017-01-12 09:42:46,468] {bash_operator.py:80} INFO - Command exited with return code 2
[2017-01-12 09:42:46,469] {models.py:1286} ERROR - Bash command failed
Traceback (most recent call last):
  File "/home/ubuntu/venv/lib/python3.5/site-packages/airflow/models.py", line 1245, in run
    result = task_copy.execute(context=context)
  File "/home/ubuntu/venv/lib/python3.5/site-packages/airflow/operators/bash_operator.py", line 83, in execute
    raise AirflowException("Bash command failed")
airflow.exceptions.AirflowException: Bash command failed
[2017-01-12 09:42:46,470] {models.py:1298} INFO - Marking task as UP_FOR_RETRY
[2017-01-12 09:42:46,483] {models.py:1327} ERROR - Bash command failed
[2017-01-12 09:43:55,633] {models.py:154} INFO - Filling up the DagBag from /home/ubuntu/airflow/dags/time_splitter.py
[2017-01-12 09:43:56,733] {models.py:154} INFO - Filling up the DagBag from /home/ubuntu/airflow/dags/time_splitter.py
[2017-01-12 09:43:56,787] {models.py:1196} INFO - 
--------------------------------------------------------------------------------
Starting attempt 2 of 2
--------------------------------------------------------------------------------

[2017-01-12 09:43:56,802] {models.py:1219} INFO - Executing <Task(BashOperator): task_2_split_time> on 2017-01-12 04:00:00
[2017-01-12 09:43:56,824] {bash_operator.py:55} INFO - tmp dir root location: 
/tmp
[2017-01-12 09:43:56,825] {bash_operator.py:64} INFO - Temporary script location :/tmp/airflowtmpe7_w759u//tmp/airflowtmpe7_w759u/task_2_split_timembehgqlu
[2017-01-12 09:43:56,825] {bash_operator.py:65} INFO - Running command: python split_into_time.py
[2017-01-12 09:43:56,828] {bash_operator.py:73} INFO - Output:
[2017-01-12 09:43:56,929] {bash_operator.py:77} INFO - python: can't open file 'split_into_time.py': [Errno 2] No such file or directory
[2017-01-12 09:43:56,931] {bash_operator.py:80} INFO - Command exited with return code 2
[2017-01-12 09:43:56,932] {models.py:1286} ERROR - Bash command failed
Traceback (most recent call last):
  File "/home/ubuntu/venv/lib/python3.5/site-packages/airflow/models.py", line 1245, in run
    result = task_copy.execute(context=context)
  File "/home/ubuntu/venv/lib/python3.5/site-packages/airflow/operators/bash_operator.py", line 83, in execute
    raise AirflowException("Bash command failed")
airflow.exceptions.AirflowException: Bash command failed
[2017-01-12 09:43:56,935] {models.py:1304} INFO - All retries failed; marking task as FAILED
[2017-01-12 09:43:56,951] {models.py:1327} ERROR - Bash command failed
