[2017-01-12 09:41:23,709] {models.py:154} INFO - Filling up the DagBag from /home/ubuntu/airflow/dags/time_splitter.py
[2017-01-12 09:41:24,467] {models.py:154} INFO - Filling up the DagBag from /home/ubuntu/airflow/dags/time_splitter.py
[2017-01-12 09:41:24,504] {models.py:1196} INFO - 
--------------------------------------------------------------------------------
Starting attempt 1 of 2
--------------------------------------------------------------------------------

[2017-01-12 09:41:24,513] {models.py:1219} INFO - Executing <Task(BashOperator): task_2_split_time> on 2017-01-12 01:30:00
[2017-01-12 09:41:24,528] {bash_operator.py:55} INFO - tmp dir root location: 
/tmp
[2017-01-12 09:41:24,529] {bash_operator.py:64} INFO - Temporary script location :/tmp/airflowtmpfg_vobq1//tmp/airflowtmpfg_vobq1/task_2_split_time1ho7q1oz
[2017-01-12 09:41:24,529] {bash_operator.py:65} INFO - Running command: python split_into_time.py
[2017-01-12 09:41:24,531] {bash_operator.py:73} INFO - Output:
[2017-01-12 09:41:24,543] {bash_operator.py:77} INFO - python: can't open file 'split_into_time.py': [Errno 2] No such file or directory
[2017-01-12 09:41:24,544] {bash_operator.py:80} INFO - Command exited with return code 2
[2017-01-12 09:41:24,544] {models.py:1286} ERROR - Bash command failed
Traceback (most recent call last):
  File "/home/ubuntu/venv/lib/python3.5/site-packages/airflow/models.py", line 1245, in run
    result = task_copy.execute(context=context)
  File "/home/ubuntu/venv/lib/python3.5/site-packages/airflow/operators/bash_operator.py", line 83, in execute
    raise AirflowException("Bash command failed")
airflow.exceptions.AirflowException: Bash command failed
[2017-01-12 09:41:24,546] {models.py:1298} INFO - Marking task as UP_FOR_RETRY
[2017-01-12 09:41:24,554] {models.py:1327} ERROR - Bash command failed
[2017-01-12 09:42:51,051] {models.py:154} INFO - Filling up the DagBag from /home/ubuntu/airflow/dags/time_splitter.py
[2017-01-12 09:42:51,886] {models.py:154} INFO - Filling up the DagBag from /home/ubuntu/airflow/dags/time_splitter.py
[2017-01-12 09:42:51,978] {models.py:1196} INFO - 
--------------------------------------------------------------------------------
Starting attempt 2 of 2
--------------------------------------------------------------------------------

[2017-01-12 09:42:51,997] {models.py:1219} INFO - Executing <Task(BashOperator): task_2_split_time> on 2017-01-12 01:30:00
[2017-01-12 09:42:52,023] {bash_operator.py:55} INFO - tmp dir root location: 
/tmp
[2017-01-12 09:42:52,027] {bash_operator.py:64} INFO - Temporary script location :/tmp/airflowtmp9ev2bjac//tmp/airflowtmp9ev2bjac/task_2_split_time3wapcbme
[2017-01-12 09:42:52,027] {bash_operator.py:65} INFO - Running command: python split_into_time.py
[2017-01-12 09:42:52,052] {bash_operator.py:73} INFO - Output:
[2017-01-12 09:42:52,208] {bash_operator.py:77} INFO - python: can't open file 'split_into_time.py': [Errno 2] No such file or directory
[2017-01-12 09:42:52,209] {bash_operator.py:80} INFO - Command exited with return code 2
[2017-01-12 09:42:52,210] {models.py:1286} ERROR - Bash command failed
Traceback (most recent call last):
  File "/home/ubuntu/venv/lib/python3.5/site-packages/airflow/models.py", line 1245, in run
    result = task_copy.execute(context=context)
  File "/home/ubuntu/venv/lib/python3.5/site-packages/airflow/operators/bash_operator.py", line 83, in execute
    raise AirflowException("Bash command failed")
airflow.exceptions.AirflowException: Bash command failed
[2017-01-12 09:42:52,212] {models.py:1304} INFO - All retries failed; marking task as FAILED
[2017-01-12 09:42:52,223] {models.py:1327} ERROR - Bash command failed
