[2017-01-12 09:43:36,333] {models.py:154} INFO - Filling up the DagBag from /home/ubuntu/airflow/dags/time_splitter.py
[2017-01-12 09:43:37,520] {models.py:154} INFO - Filling up the DagBag from /home/ubuntu/airflow/dags/time_splitter.py
[2017-01-12 09:43:37,558] {models.py:1196} INFO - 
--------------------------------------------------------------------------------
Starting attempt 1 of 2
--------------------------------------------------------------------------------

[2017-01-12 09:43:37,566] {models.py:1219} INFO - Executing <Task(BashOperator): task_2_split_time> on 2017-01-12 05:00:00
[2017-01-12 09:43:37,581] {bash_operator.py:55} INFO - tmp dir root location: 
/tmp
[2017-01-12 09:43:37,582] {bash_operator.py:64} INFO - Temporary script location :/tmp/airflowtmpj84id5d4//tmp/airflowtmpj84id5d4/task_2_split_timehtd4khx0
[2017-01-12 09:43:37,582] {bash_operator.py:65} INFO - Running command: python split_into_time.py
[2017-01-12 09:43:37,584] {bash_operator.py:73} INFO - Output:
[2017-01-12 09:43:37,598] {bash_operator.py:77} INFO - python: can't open file 'split_into_time.py': [Errno 2] No such file or directory
[2017-01-12 09:43:37,599] {bash_operator.py:80} INFO - Command exited with return code 2
[2017-01-12 09:43:37,599] {models.py:1286} ERROR - Bash command failed
Traceback (most recent call last):
  File "/home/ubuntu/venv/lib/python3.5/site-packages/airflow/models.py", line 1245, in run
    result = task_copy.execute(context=context)
  File "/home/ubuntu/venv/lib/python3.5/site-packages/airflow/operators/bash_operator.py", line 83, in execute
    raise AirflowException("Bash command failed")
airflow.exceptions.AirflowException: Bash command failed
[2017-01-12 09:43:37,601] {models.py:1298} INFO - Marking task as UP_FOR_RETRY
[2017-01-12 09:43:37,609] {models.py:1327} ERROR - Bash command failed
[2017-01-12 09:44:53,579] {models.py:154} INFO - Filling up the DagBag from /home/ubuntu/airflow/dags/time_splitter.py
[2017-01-12 09:44:54,600] {models.py:154} INFO - Filling up the DagBag from /home/ubuntu/airflow/dags/time_splitter.py
[2017-01-12 09:44:54,709] {models.py:1196} INFO - 
--------------------------------------------------------------------------------
Starting attempt 2 of 2
--------------------------------------------------------------------------------

[2017-01-12 09:44:54,761] {models.py:1219} INFO - Executing <Task(BashOperator): task_2_split_time> on 2017-01-12 05:00:00
[2017-01-12 09:44:54,785] {bash_operator.py:55} INFO - tmp dir root location: 
/tmp
[2017-01-12 09:44:54,786] {bash_operator.py:64} INFO - Temporary script location :/tmp/airflowtmp1ibdakvx//tmp/airflowtmp1ibdakvx/task_2_split_timee2ry6ia4
[2017-01-12 09:44:54,786] {bash_operator.py:65} INFO - Running command: python split_into_time.py
[2017-01-12 09:44:54,788] {bash_operator.py:73} INFO - Output:
[2017-01-12 09:44:54,802] {bash_operator.py:77} INFO - python: can't open file 'split_into_time.py': [Errno 2] No such file or directory
[2017-01-12 09:44:54,803] {bash_operator.py:80} INFO - Command exited with return code 2
[2017-01-12 09:44:54,804] {models.py:1286} ERROR - Bash command failed
Traceback (most recent call last):
  File "/home/ubuntu/venv/lib/python3.5/site-packages/airflow/models.py", line 1245, in run
    result = task_copy.execute(context=context)
  File "/home/ubuntu/venv/lib/python3.5/site-packages/airflow/operators/bash_operator.py", line 83, in execute
    raise AirflowException("Bash command failed")
airflow.exceptions.AirflowException: Bash command failed
[2017-01-12 09:44:54,805] {models.py:1304} INFO - All retries failed; marking task as FAILED
[2017-01-12 09:44:54,815] {models.py:1327} ERROR - Bash command failed
