[2017-01-12 09:44:33,684] {models.py:154} INFO - Filling up the DagBag from /home/ubuntu/airflow/dags/time_splitter.py
[2017-01-12 09:44:35,001] {models.py:154} INFO - Filling up the DagBag from /home/ubuntu/airflow/dags/time_splitter.py
[2017-01-12 09:44:35,042] {models.py:1196} INFO - 
--------------------------------------------------------------------------------
Starting attempt 1 of 2
--------------------------------------------------------------------------------

[2017-01-12 09:44:35,051] {models.py:1219} INFO - Executing <Task(BashOperator): task_2_split_time> on 2017-01-12 06:30:00
[2017-01-12 09:44:35,070] {bash_operator.py:55} INFO - tmp dir root location: 
/tmp
[2017-01-12 09:44:35,071] {bash_operator.py:64} INFO - Temporary script location :/tmp/airflowtmp92dgh6d5//tmp/airflowtmp92dgh6d5/task_2_split_time_nraay6n
[2017-01-12 09:44:35,071] {bash_operator.py:65} INFO - Running command: python split_into_time.py
[2017-01-12 09:44:35,072] {bash_operator.py:73} INFO - Output:
[2017-01-12 09:44:35,086] {bash_operator.py:77} INFO - python: can't open file 'split_into_time.py': [Errno 2] No such file or directory
[2017-01-12 09:44:35,087] {bash_operator.py:80} INFO - Command exited with return code 2
[2017-01-12 09:44:35,087] {models.py:1286} ERROR - Bash command failed
Traceback (most recent call last):
  File "/home/ubuntu/venv/lib/python3.5/site-packages/airflow/models.py", line 1245, in run
    result = task_copy.execute(context=context)
  File "/home/ubuntu/venv/lib/python3.5/site-packages/airflow/operators/bash_operator.py", line 83, in execute
    raise AirflowException("Bash command failed")
airflow.exceptions.AirflowException: Bash command failed
[2017-01-12 09:44:35,089] {models.py:1298} INFO - Marking task as UP_FOR_RETRY
[2017-01-12 09:44:35,097] {models.py:1327} ERROR - Bash command failed
[2017-01-12 09:45:40,220] {models.py:154} INFO - Filling up the DagBag from /home/ubuntu/airflow/dags/time_splitter.py
[2017-01-12 09:45:40,983] {models.py:154} INFO - Filling up the DagBag from /home/ubuntu/airflow/dags/time_splitter.py
[2017-01-12 09:45:41,023] {models.py:1196} INFO - 
--------------------------------------------------------------------------------
Starting attempt 2 of 2
--------------------------------------------------------------------------------

[2017-01-12 09:45:41,032] {models.py:1219} INFO - Executing <Task(BashOperator): task_2_split_time> on 2017-01-12 06:30:00
[2017-01-12 09:45:41,048] {bash_operator.py:55} INFO - tmp dir root location: 
/tmp
[2017-01-12 09:45:41,048] {bash_operator.py:64} INFO - Temporary script location :/tmp/airflowtmp_g5lrwxf//tmp/airflowtmp_g5lrwxf/task_2_split_timejvttjd9k
[2017-01-12 09:45:41,048] {bash_operator.py:65} INFO - Running command: python split_into_time.py
[2017-01-12 09:45:41,050] {bash_operator.py:73} INFO - Output:
[2017-01-12 09:45:41,064] {bash_operator.py:77} INFO - python: can't open file 'split_into_time.py': [Errno 2] No such file or directory
[2017-01-12 09:45:41,065] {bash_operator.py:80} INFO - Command exited with return code 2
[2017-01-12 09:45:41,065] {models.py:1286} ERROR - Bash command failed
Traceback (most recent call last):
  File "/home/ubuntu/venv/lib/python3.5/site-packages/airflow/models.py", line 1245, in run
    result = task_copy.execute(context=context)
  File "/home/ubuntu/venv/lib/python3.5/site-packages/airflow/operators/bash_operator.py", line 83, in execute
    raise AirflowException("Bash command failed")
airflow.exceptions.AirflowException: Bash command failed
[2017-01-12 09:45:41,066] {models.py:1304} INFO - All retries failed; marking task as FAILED
[2017-01-12 09:45:41,075] {models.py:1327} ERROR - Bash command failed
