[2017-01-12 09:41:49,004] {models.py:154} INFO - Filling up the DagBag from /home/ubuntu/airflow/dags/time_splitter.py
[2017-01-12 09:41:49,927] {models.py:154} INFO - Filling up the DagBag from /home/ubuntu/airflow/dags/time_splitter.py
[2017-01-12 09:41:49,970] {models.py:1196} INFO - 
--------------------------------------------------------------------------------
Starting attempt 1 of 2
--------------------------------------------------------------------------------

[2017-01-12 09:41:49,980] {models.py:1219} INFO - Executing <Task(BashOperator): task_2_split_time> on 2017-01-12 02:30:00
[2017-01-12 09:41:49,996] {bash_operator.py:55} INFO - tmp dir root location: 
/tmp
[2017-01-12 09:41:49,997] {bash_operator.py:64} INFO - Temporary script location :/tmp/airflowtmpg4irl2kd//tmp/airflowtmpg4irl2kd/task_2_split_timegba7mxgw
[2017-01-12 09:41:49,997] {bash_operator.py:65} INFO - Running command: python split_into_time.py
[2017-01-12 09:41:49,999] {bash_operator.py:73} INFO - Output:
[2017-01-12 09:41:50,014] {bash_operator.py:77} INFO - python: can't open file 'split_into_time.py': [Errno 2] No such file or directory
[2017-01-12 09:41:50,015] {bash_operator.py:80} INFO - Command exited with return code 2
[2017-01-12 09:41:50,015] {models.py:1286} ERROR - Bash command failed
Traceback (most recent call last):
  File "/home/ubuntu/venv/lib/python3.5/site-packages/airflow/models.py", line 1245, in run
    result = task_copy.execute(context=context)
  File "/home/ubuntu/venv/lib/python3.5/site-packages/airflow/operators/bash_operator.py", line 83, in execute
    raise AirflowException("Bash command failed")
airflow.exceptions.AirflowException: Bash command failed
[2017-01-12 09:41:50,016] {models.py:1298} INFO - Marking task as UP_FOR_RETRY
[2017-01-12 09:41:50,026] {models.py:1327} ERROR - Bash command failed
[2017-01-12 09:43:16,702] {models.py:154} INFO - Filling up the DagBag from /home/ubuntu/airflow/dags/time_splitter.py
[2017-01-12 09:43:17,868] {models.py:154} INFO - Filling up the DagBag from /home/ubuntu/airflow/dags/time_splitter.py
[2017-01-12 09:43:17,911] {models.py:1196} INFO - 
--------------------------------------------------------------------------------
Starting attempt 2 of 2
--------------------------------------------------------------------------------

[2017-01-12 09:43:17,922] {models.py:1219} INFO - Executing <Task(BashOperator): task_2_split_time> on 2017-01-12 02:30:00
[2017-01-12 09:43:17,938] {bash_operator.py:55} INFO - tmp dir root location: 
/tmp
[2017-01-12 09:43:17,939] {bash_operator.py:64} INFO - Temporary script location :/tmp/airflowtmp7iown0uk//tmp/airflowtmp7iown0uk/task_2_split_timen3xc7ryu
[2017-01-12 09:43:17,939] {bash_operator.py:65} INFO - Running command: python split_into_time.py
[2017-01-12 09:43:17,941] {bash_operator.py:73} INFO - Output:
[2017-01-12 09:43:17,955] {bash_operator.py:77} INFO - python: can't open file 'split_into_time.py': [Errno 2] No such file or directory
[2017-01-12 09:43:17,955] {bash_operator.py:80} INFO - Command exited with return code 2
[2017-01-12 09:43:17,956] {models.py:1286} ERROR - Bash command failed
Traceback (most recent call last):
  File "/home/ubuntu/venv/lib/python3.5/site-packages/airflow/models.py", line 1245, in run
    result = task_copy.execute(context=context)
  File "/home/ubuntu/venv/lib/python3.5/site-packages/airflow/operators/bash_operator.py", line 83, in execute
    raise AirflowException("Bash command failed")
airflow.exceptions.AirflowException: Bash command failed
[2017-01-12 09:43:17,957] {models.py:1304} INFO - All retries failed; marking task as FAILED
[2017-01-12 09:43:17,964] {models.py:1327} ERROR - Bash command failed
