[2017-01-12 09:45:09,822] {models.py:154} INFO - Filling up the DagBag from /home/ubuntu/airflow/dags/time_splitter.py
[2017-01-12 09:45:11,487] {models.py:154} INFO - Filling up the DagBag from /home/ubuntu/airflow/dags/time_splitter.py
[2017-01-12 09:45:11,531] {models.py:1196} INFO - 
--------------------------------------------------------------------------------
Starting attempt 1 of 2
--------------------------------------------------------------------------------

[2017-01-12 09:45:11,540] {models.py:1219} INFO - Executing <Task(BashOperator): task_2_split_time> on 2017-01-12 07:30:00
[2017-01-12 09:45:11,557] {bash_operator.py:55} INFO - tmp dir root location: 
/tmp
[2017-01-12 09:45:11,558] {bash_operator.py:64} INFO - Temporary script location :/tmp/airflowtmpkot37ism//tmp/airflowtmpkot37ism/task_2_split_timep2n7ld3w
[2017-01-12 09:45:11,558] {bash_operator.py:65} INFO - Running command: python split_into_time.py
[2017-01-12 09:45:11,560] {bash_operator.py:73} INFO - Output:
[2017-01-12 09:45:11,574] {bash_operator.py:77} INFO - python: can't open file 'split_into_time.py': [Errno 2] No such file or directory
[2017-01-12 09:45:11,575] {bash_operator.py:80} INFO - Command exited with return code 2
[2017-01-12 09:45:11,575] {models.py:1286} ERROR - Bash command failed
Traceback (most recent call last):
  File "/home/ubuntu/venv/lib/python3.5/site-packages/airflow/models.py", line 1245, in run
    result = task_copy.execute(context=context)
  File "/home/ubuntu/venv/lib/python3.5/site-packages/airflow/operators/bash_operator.py", line 83, in execute
    raise AirflowException("Bash command failed")
airflow.exceptions.AirflowException: Bash command failed
[2017-01-12 09:45:11,577] {models.py:1298} INFO - Marking task as UP_FOR_RETRY
[2017-01-12 09:45:11,585] {models.py:1327} ERROR - Bash command failed
[2017-01-12 09:46:12,822] {models.py:154} INFO - Filling up the DagBag from /home/ubuntu/airflow/dags/time_splitter.py
[2017-01-12 09:46:13,585] {models.py:154} INFO - Filling up the DagBag from /home/ubuntu/airflow/dags/time_splitter.py
[2017-01-12 09:46:13,622] {models.py:1196} INFO - 
--------------------------------------------------------------------------------
Starting attempt 2 of 2
--------------------------------------------------------------------------------

[2017-01-12 09:46:13,631] {models.py:1219} INFO - Executing <Task(BashOperator): task_2_split_time> on 2017-01-12 07:30:00
[2017-01-12 09:46:13,646] {bash_operator.py:55} INFO - tmp dir root location: 
/tmp
[2017-01-12 09:46:13,647] {bash_operator.py:64} INFO - Temporary script location :/tmp/airflowtmpuk9hnwi0//tmp/airflowtmpuk9hnwi0/task_2_split_timer1qvudwa
[2017-01-12 09:46:13,647] {bash_operator.py:65} INFO - Running command: python split_into_time.py
[2017-01-12 09:46:13,649] {bash_operator.py:73} INFO - Output:
[2017-01-12 09:46:13,662] {bash_operator.py:77} INFO - python: can't open file 'split_into_time.py': [Errno 2] No such file or directory
[2017-01-12 09:46:13,663] {bash_operator.py:80} INFO - Command exited with return code 2
[2017-01-12 09:46:13,663] {models.py:1286} ERROR - Bash command failed
Traceback (most recent call last):
  File "/home/ubuntu/venv/lib/python3.5/site-packages/airflow/models.py", line 1245, in run
    result = task_copy.execute(context=context)
  File "/home/ubuntu/venv/lib/python3.5/site-packages/airflow/operators/bash_operator.py", line 83, in execute
    raise AirflowException("Bash command failed")
airflow.exceptions.AirflowException: Bash command failed
[2017-01-12 09:46:13,664] {models.py:1304} INFO - All retries failed; marking task as FAILED
[2017-01-12 09:46:13,671] {models.py:1327} ERROR - Bash command failed
